Workbook

Sheet Summary
A1: holroyd howe
A3: Check prices regulary
A5: Stock Sumary W/E | B5: 22.04.26
A7: Food Totals
A8: Dry stores | B8: =SUM(Dry_Stores!E150) -> 24.472
A9: FOH | B9: =SUM(FOH!E83) -> 1217.845
A10: Fish | B10: =SUM(Fish!E16) -> 59.69
A11: Frozen | B11: =SUM(Frozen!E85) -> 350.474
A12: Bakery | B12: =SUM(Bakery!E33) -> 37.75
A13: Meat | B13: =SUM(Meat!E50) -> 62.2
A14: Dairy | B14: =SUM(Dairy!E52) -> 0
A15: Fruit & Veg | B15: =SUM('Fruit_&_Veg'!F114) -> 234.145
A16: Pastry | B16: =SUM(Pastry!E80) -> 701.575
A17: Retail | B17: =SUM(Retail!E14) -> 114.78
A18: FOOD TOTAL | B18: =SUM(B8:B17) -> 2802.931
A19: CLEANING TOTAL | B19: =SUM(Cleaning!F59) -> 1941.099
A20: DISPOSABLES TOTAL | B20: =SUM(Disposables!E49) -> 1646.668

Sheet Dry_Stores
A1: holroyd howe
A2: DRY STORES
A4: ITEM | B4: UNIT | C4: PRICE | D4: QUANTITY | E4: TOTAL
A5: Pulses & Grains | E5: =SUM(C5*D5) -> 0
A6: Misc invoices bidfood/ foodari | C6: 250 | E6: =SUM(C6*D6) -> 0
A7: black eyed beans | B7: 3kg | C7: 6.66 | D7: 2 | E7: =C7*D7 -> 13.32
A8: Cous Cous Giant | B8: 1kg | C8: 3.28 | D8: 4 | E8: =SUM(C8*D8) -> 13.12
A9: lentils | B9: 3kg | C9: 5.73 | D9: 4 | E9: =SUM(C9*D9) -> 22.92
A10: moroccan cous cous | B10: 1.5g | D10: 0 | E10: =SUM(C10*D10) -> 0
A11: indian cous cous | B11: 1.5kg | D11: 0 | E11: =SUM(C11*D11) -> 0
A12: 3 colour quinoa | B12: 500g | C12: 2.93 | D12: 0 | E12: =SUM(C12*D12) -> 0
A13: Pasta & Rice | E13: =SUM(C13*D13) -> 0
A14: chop suye noodles | B14: 9kg | C14: 37.11 | D14: 0 | E14: =C14*D14 -> 0
A15: Egg Noodles | B15: 3kg | C15: 14.17 | E15: =SUM(C15*D15) -> 0
A16: Rice noodles | B16: 3kg | C16: 4.68 | D16: 5 | E16: =SUM(C16*D16) -> 23.4
A17: Gnocci | B17: 500g | C17: 1.74 | D17: 2 | E17: =SUM(C17*D17) -> 3.48
A18: Gluten Free Pasta | B18: 1kg | C18: =49.02/8 -> 6.1275 | D18: 6 | E18: =SUM(C18*D18) -> 36.765
A19: Fusilli Pasta | B19: 3kg | C19: 7.1 | D19: 0 | E19: =SUM(C19*D19) -> 0
A20: Penne Pasta | B20: 3kg | C20: 21.49 | D20: 0 | E20: =SUM(C20*D20) -> 0
A21: Lasagne - Gluten free | B21: 250gr | C21: 4.56 | D21: 7 | E21: =SUM(C21*D21) -> 31.92
A22: Lasagne Sheets | B22: 500g | C22: 1.19 | D22: 27 | E22: =SUM(C22*D22) -> 32.13
A23: Macaroni | B23: 3kg | C23: 3.97 | D23: 3 | E23: =SUM(C23*D23) -> 11.91
A24: rigatoni pasta | B24: 3kg | C24: =22/4 -> 5.5 | D24: 3.5 | E24: =SUM(D24*C24) -> 19.25
A25: wholeweat | B25: 3kg | D25: 8
A26: Spaghetti - Gluten free | B26: 500g | C26: 2.53 | D26: 0 | E26: =SUM(C26*D26) -> 0
A27: Rice | E27: =SUM(C27*D27) -> 0
A28: Rice arborio | B28: 1kg | C28: 2.39 | D28: 0 | E28: =SUM(C28*D28) -> 0
A29: Long grain easy cook | B29: 15kg | C29: 20.28 | D29: 1 | E29: =SUM(C29*D29) -> 20.28
A30: Bulgar wheat | B30: 3kg | C30: 6.78 | D30: 0 | E30: =SUM(C30*D30) -> 0
A31: Rice pudding | B31: 3kg | C31: 4.98 | D31: 0 | E31: =SUM(C31*D31) -> 0
A32: Tinned Goods | E32: =SUM(C32*D32) -> 0
A33: Tuna Chunks | B33: 1.7KG | C33: 11.61 | D33: 0 | E33: =SUM(C33*D33) -> 0
A34: Solid Pack apples | B34: 2.5kg | C34: 3.94 | D34: 0 | E34: =SUM(C34*D34) -> 0
A35: Baked Beans | B35: 3.12 kg | C35: 3.42 | D35: 8 | E35: =SUM(C35*D35) -> 27.36
A36: Butter beans | B36: 2.5kg | C36: 2.82 | D36: 1 | E36: =SUM(C36*D36) -> 2.82
A37: Mushy Peas | B37: 2.52kg | C37: 5.52 | D37: 0 | E37: =SUM(C37*D37) -> 0
A38: 5 bean salad | B38: 800g | C38: 3.18 | D38: 0 | E38: =SUM(C38*D38) -> 0
A39: Chick Peas | B39: 2.5kg | C39: 7.64 | D39: 1 | E39: =SUM(C39*D39) -> 7.64
A40: Condensed milk | B40: 397g | C40: 1.98 | D40: 0 | E40: =SUM(C40*D40) -> 0
A41: Coconut milk | B41: 400ml | C41: 1.16 | D41: 0 | E41: =SUM(C41*D41) -> 0
...

Sheet Pastry
A1: holroyd howe
A3: PASTRY
A4: ITEM | B4: UNIT | C4: PRICE | D4: QUANTITY | E4: TOTAL
A5: CUSTARD POWDER | B5: 3.5 kg | C5: 3.09 | D5: 0.6 | E5: =C5*D5 -> 1.854
A6: Desiccated coconut | B6: 2kg | C6: 8.18 | D6: 0 | E6: =C6*D6 -> 0
A7: Digestive biscuit bulk pack | B7: 300g | C7: 0.68 | D7: 12 | E7: =C7*D7 -> 8.16
A8: bourbon | E8: =C8*D8 -> 0
A9: Dried Fruit | E9: =C9*D9 -> 0
A10: Apricots chopped | B10: 1kg | C10: 4.52 | E10: =C10*D10 -> 0
A11: Banana chips | B11: 1 kg | C11: 10.33 | D11: 1 | E11: =C11*D11 -> 10.33
A12: Cranberrys | B12: 1kg | C12: 10.23 | D12: 0 | E12: =C12*D12 -> 0
A13: Dates | B13: 3kg | C13: 17.81 | D13: 1 | E13: =C13*D13 -> 17.81
A14: Glace Cherrys | B14: 5kg | C14: 22.4 | D14: 0 | E14: =C14*D14 -> 0
A15: apricots whole | B15: 3kg | D15: 0 | E15: =C15*D15 -> 0
A16: Prunes | B16: 3kg | C16: 14.23 | D16: 0 | E16: =C16*D16 -> 0
A17: Sultanas | B17: 3kg | C17: 7.59 | D17: 3 | E17: =C17*D17 -> 22.77
A18: Flour | E18: =C18*D18 -> 0
A19: Bread roll mix | B19: 3.5kg | C19: 4.44 | D19: 0 | E19: =C19*D19 -> 0
A20: Cornflour | B20: 3.5kg | C20: 7.22 | D20: 0.6 | E20: =C20*D20 -> 4.332
A21: strong flour | B21: 16kg | C21: 32.5 | D21: 0.5 | E21: =C21*D21 -> 16.25
A22: Plain | B22: 16 kg | C22: 10.82 | D22: 1.4 | E22: =C22*D22 -> 15.148
A23: plain flour | B23: 1.5kg | D23: 0 | E23: =C23*D23 -> 0
A24: Self Raising | B24: 16 kg | C24: 10.95 | D24: 0.9 | E24: =C24*D24 -> 9.855
A25: Wholemeal flour | B25: 1.5kg | C25: 1.29 | D25: 4 | E25: =C25*D25 -> 5.16
A26: Jelly Orange | B26: 3.5kg | C26: 3.67 | D26: 0 | E26: =C26*D26 -> 0
A27: Jelly Raspberry | B27: 3.5kg | C27: 14.69 | D27: 0 | E27: =C27*D27 -> 0
A28: Jelly Lime | B28: 3.5kg | C28: 7.49 | D28: 0 | E28: =C28*D28 -> 0
A29: Jelly Strawberry | B29: 3.5kg | C29: 6.25 | D29: 0 | E29: =C29*D29 -> 0
A30: Veg Jelly orange | B30: 3.5kg | C30: 26.2 | E30: =C30*D30 -> 0
A31: Veg Jelly strawberry | B31: 3.5kg | C31: 30.73 | D31: 2 | E31: =C31*D31 -> 61.46
A32: Sugars | E32: =C32*D32 -> 0
A33: Caster sugar | B33: 25kg | C33: 34.23 | D33: 0.8 | E33: =C33*D33 -> 27.384
A34: Demerara | B34: 3kg | C34: 6.95 | D34: 3 | E34: =C34*D34 -> 20.85
A35: Granulated sugar | B35: 2kg | C35: 2.74 | E35: =C35*D35 -> 0
A36: Tate & Lyle icing | B36: 500g | C36: 1.34 | D36: 2 | E36: =C36*D36 -> 2.68
A37: Soft dark brown | B37: 3kg | C37: 7.4 | D37: 1 | E37: =C37*D37 -> 7.4
A38: Soft light brown | B38: 3kg | C38: 10.54 | D38: 0 | E38: =C38*D38 -> 0
A39: Sugar strands | B39: 750g | C39: 7.39 | D39: 0 | E39: =C39*D39 -> 0
A40: Golden syrup | B40: 7.26 kg | C40: 14.57 | D40: 1 | E40: =C40*D40 -> 14.57
A41: Maple syrup | B41: 454g | C41: 1.81 | D41: 4 | E41: =C41*D41 -> 7.24
...

Sheet FOH
A3: FOH
A5: ITEM | B5: UNIT | C5: PRICE | D5: QUANTITY | E5: TOTAL
A6: Juice & drinks
A7: Apple juice | B7: 1ltr | C7: 0.83 | D7: 48 | E7: =C7*D7 -> 39.84
A8: Tropical fruit juice | B8: 1 litre | C8: 0.66 | D8: 0 | E8: =C8*D8 -> 0
A9: Orange juice | B9: 1ltr | C9: 0.88 | D9: 12 | E9: =C9*D9 -> 10.56
E10: =C10*D10 -> 0
A11: Apple juice carton | B11: each | C11: 0.26 | D11: 72 | E11: =C11*D11 -> 18.72
A12: Orange juice carton | B12: each | C12: 0.26 | D12: 0 | E12: =C12*D12 -> 0
A13: Lemon squash (Brakes) | B13: 5 litre | C13: 3.93 | D13: 0 | E13: =C13*D13 -> 0
A14: Orange squash (Brakes) | B14: 5 litre | C14: 4.72 | D14: 1.3 | E14: =C14*D14 -> 6.136
A15: Blackcurrant squash | B15: 5 Litre | C15: 8.71 | D15: 2.3 | E15: =C15*D15 -> 20.033
E16: =C16*D16 -> 0
E17: =C17*D17 -> 0
E18: =C18*D18 -> 0
A19: Digestive Biscuit | B19: x300g | C19: 0.69 | D19: 11 | E19: =C19*D19 -> 7.59
A20: Chocolate Digestive | B20: x300g | C20: 1.54 | D20: 0 | E20: =C20*D20 -> 0
A21: Elderflower | B21: 500ml | C21: 3.13 | D21: 15 | E21: =C21*D21 -> 46.95
A22: Harrogatespring water still Glass bootle | B22: 1ltr | C22: 0.7 | D22: 64 | E22: =C22*D22 -> 44.8
A23: Milk Chocolate teacakes | B23: each | C23: 0.23 | D23: 0 | E23: =C23*D23 -> 0
A24: Harrogatespring water still 330ml | B24: 1x30 | C24: 5.75 | D24: 5 | E24: =C24*D24 -> 28.75
A25: Biscuits | E25: =C25*D25 -> 0
A26: Rich Tea | B26: 300g | C26: 0.75 | D26: 24 | E26: =C26*D26 -> 18
A27: Bourbon creams ( 12x300g) | B27: 300g | C27: 1.49 | D27: 48 | E27: =C27*D27 -> 71.52
A28: Tunnocks caramel wafer | B28: each | C28: 0.25 | D28: 0 | E28: =C28*D28 -> 0
A29: Gluten free biscuits (bidfood) | B29: 1*60 pack | C29: 29.04 | D29: 1 | E29: =C29*D29 -> 29.04
A30: Custard creams (3663 12x300g) | B30: 300g | C30: 1.62 | D30: 24 | E30: =C30*D30 -> 38.88
A31: Pink waffers | B31: 100g | C31: 0.69 | D31: 0 | E31: =C31*D31 -> 0
A32: Jammy dodgers (Brakes 18 x 140g) | B32: 140g pack | C32: 1.09 | D32: 0 | E32: =C32*D32 -> 0
A33: EFAV biscuits assorted | B33: 2kg | C33: 11.59 | D33: 3 | E33: =C33*D33 -> 34.77
A34: Kallo dark chocolate | B34: 1 box | D34: 0 | E34: =C34*D34 -> 0
A35: Milky way | B35: each | C35: 0.23 | D35: 0 | E35: =C35*D35 -> 0
A36: Coffee & tea | E36: =C36*D36 -> 0
A37: Coffee granuals Decaf Nescafe (3663) | B37: 750g | C37: 20.65 | D37: 0 | E37: =C37*D37 -> 0
A38: Coffee granuals Nescafe REFILL | B38: 600g | C38: 18.83 | E38: =C38*D38 -> 0
A39: Filter coffee | B39: 60g pouch | C39: 1.83 | D39: 200 | E39: =C39*D39 -> 366
A40: Cocoa Powder | B40: 1kg | C40: 0 | E40: =C40*D40 -> 0
A41: EFAV Chocolate powder | B41: 1kg | C41: 7.28 | D41: 0 | E41: =C41*D41 -> 0
A42: Drinking chocolate | B42: 5kg | C42: 28.39 | D42: 1.3 | E42: =C42*D42 -> 36.907
A43: Drinking chocolate - Cadbury's | B43: 2kg | C43: 18.61 | D43: 0 | E43: =C43*D43 -> 0
...

Sheet Fish
A1: holroyd howe
A2: Fish
A4: ITEM | B4: UNIT | C4: PRICE | D4: QUANTITY | E4: TOTAL
A5: Cod fishfingers | C5: 46.61 | D5: 0 | E5: =C5*D5 -> 0
A6: jumbo fish fingers M&J 35x71g | B6: box | C6: 23.93 | D6: 0 | E6: =C6*D6 -> 0
A7: Mackrell fillets (18x2x60-100gr) | B7: box | C7: 46.63 | D7: 0 | E7: =C7*D7 -> 0
A8: Pollock fillet breaded 1x24(M&J)7026 | B8: box | C8: 22.52 | E8: =C8*D8 -> 0
A9: Bidfood Battered Pollock | B9: 1x36 | C9: 24.78 | D9: 2 | E9: =C9*D9 -> 49.56
A10: Pollock fillet | B10: 1x25 | C10: 24.6 | E10: =C10*D10 -> 0
A11: Prawn - cold water | B11: 2kg | C11: 24.36 | D11: 0 | E11: =C11*D11 -> 0
A12: Gluten free fish finger | B12: box | C12: 25.06 | D12: 0 | E12: =C12*D12 -> 0
A13: Gluten free battered pollock | B13: 60x60 80g | C13: 37.9 | D13: 0 | E13: =C13*D13 -> 0
A14: Bidfood fishcake | B14: x24 | C14: 9.48 | E14: =C14*D14 -> 0
A15: Smoked salmon | B15: 890g | C15: 20.26 | D15: 0.5 | E15: =C15*D15 -> 10.13
A16: Total | E16: =SUM(E5:E15) -> 59.69

Sheet Bakery
A1: holroyd howe
A2: Bakery
A4: ITEM | B4: UNIT | C4: PRICE | D4: QUANTITY | E4: TOTAL
A5: Bagels
A6: Bloomer - granary 800g | B6: each | C6: 2.34 | E6: =C6*D6 -> 0
A7: Hot Dog Rolls (WHD) | B7: 4's | C7: 1.29 | D7: 0 | E7: =C7*D7 -> 0
A8: Home Made bread | B8: loaf | C8: 0.92 | E8: =C8*D8 -> 0
A9: Burger Baps Americana 4.5in bun | B9: 48's | C9: 6.24 | D9: 0 | E9: =C9*D9 -> 0
A10: Tortilla Wraps (bidfood) | B10: each | C10: 0.21 | D10: 6 | E10: =C10*D10 -> 1.26
A11: Pitta Bread | B11: 6pck | C11: 0.79 | D11: 0 | E11: =C11*D11 -> 0
A12: B free bread | B12: each | C12: 2.86 | D12: 0 | E12: =C12*D12 -> 0
A13: Fletchers bread brown | B13: xeach | C13: 1.05 | D13: 0 | E13: =C13*D13 -> 0
A14: Assorted canape bread (10 per box) | B14: each | C14: 3.6 | D14: 0 | E14: =C14*D14 -> 0
A15: Hovis white | B15: each | C15: 1.33 | D15: 14 | E15: =C15*D15 -> 18.62
A16: hovis brown | B16: each | C16: 1.3 | D16: 2 | E16: =C16*D16 -> 2.6
A17: Brioche rolls | B17: x6 | C17: 2.46 | D17: 0 | E17: =C17*D17 -> 0
A18: Schar GF ciabatta | B18: x30 | C18: 27.26 | D18: 0 | E18: =C18*D18 -> 0
A19: Breakfast Muffins WHD | B19: x4 | C19: 1.09 | D19: 3 | E19: =C19*D19 -> 3.27
A20: Brioche Buns WHD | B20: 1x6 | C20: 2.64 | D20: 0 | E20: =C20*D20 -> 0
A21: Mini Naan | B21: 16x6x35 | C21: 22.7 | D21: 0 | E21: =C21*D21 -> 0
A22: Cakes & traybakes | C22: 0 | E22: =C22*D22 -> 0
A23: Jellies | B23: each | C23: 0.08 | D23: 0 | E23: =C23*D23 -> 0
A24: Homemade hot pudding | B24: each | C24: 0.28 | E24: =C24*D24 -> 0
A25: homemade flapjack | B25: each | C25: 0.24 | D25: 0 | E25: =C25*D25 -> 0
A26: homemade traybakes | B26: each | C26: 0.24 | D26: 50 | E26: =C26*D26 -> 12
A27: GF Genius bread | B27: each | C27: 4.33 | D27: 0 | E27: =C27*D27 -> 0
A28: GF Flapjack | B28: portion | C28: 0.85 | D28: 0 | E28: =C28*D28 -> 0
A29: GF Caramel shortcake | B29: PORTION | C29: 1.07 | D29: 0 | E29: =C29*D29 -> 0
A30: GF sour dough WHD BAGEL | B30: each | C30: 1.43 | D30: 0 | E30: =C30*D30 -> 0
A31: Gluten free Italian GF rolls | B31: x4 | C31: 4.63 | D31: 0 | E31: =C31*D31 -> 0
A32: Gf flapjack | B32: 1 x 18 | C32: 15.34 | D32: 0 | E32: =C32*D32 -> 0
A33: Total | E33: =SUM(E6:E32) -> 37.75

Sheet Meat
A2: Meat
A4: ITEM | B4: UNIT | C4: PRICE | D4: QUANTITY | E4: TOTAL
A5: Bacon - Green Back sliced rindless BPM | B5: 2kg | C5: 6.41 | E5: =C5*D5 -> 0
A6: Bacon bidfood | B6: 2.27 | C6: 15.03 | D6: 1 | E6: =C6*D6 -> 15.03
A7: Bacon - streaky | B7: 5lb | C7: 16.69 | E7: =C7*D7 -> 0
A8: Beef | E8: =C8*D8 -> 0
A9: Minced beef BPM | B9: KG | C9: 12.6 | D9: 3 | E9: =C9*D9 -> 37.8
A10: Chuck steak diced | B10: KG | C10: 9.8 | D10: 0 | E10: =C10*D10 -> 0
A11: Beef Stir Fry | B11: kg | C11: 9.86 | E11: =C11*D11 -> 0
A12: Burgers | B12: each | C12: 0.47 | E12: =C12*D12 -> 0
A13: Chicken | E13: =C13*D13 -> 0
A14: Diced breast | B14: kg | C14: 6.28 | E14: =C14*D14 -> 0
A15: Diced 50/50 | B15: KG | C15: 9.68 | E15: =C15*D15 -> 0
A16: Chicken strir fry BPM | B16: kg | C16: 7.3 | E16: =C16*D16 -> 0
A17: Chicken wings | B17: kg | C17: 3.53 | E17: =C17*D17 -> 0
A18: Supreme 5oz boneless BPM | B18: each | C18: 1.25 | E18: =C18*D18 -> 0
A19: Chicken Fillets 4-5oz | B19: each | C19: 0.91 | E19: =C19*D19 -> 0
A20: Chicken thighs bone off | B20: each | C20: 0.68 | D20: 0 | E20: =C20*D20 -> 0
A21: Chicken sausage | B21: box | C21: 18 | E21: =C21*D21 -> 0
A22: Lamb | E22: =C22*D22 -> 0
A23: Diced lamb | B23: kg | C23: 13.89 | E23: =C23*D23 -> 0
A24: Minced | B24: 1kg | C24: 9.21 | E24: =C24*D24 -> 0
A25: Hotdogs BPM | B25: x18 | C25: 10.99 | E25: =C25*D25 -> 0
A26: Pork | E26: =C26*D26 -> 0
A27: Short Loin pork boned & rolled BPM | B27: kg | C27: 6.22 | E27: =C27*D27 -> 0
A28: Pork steaks 4-5oz | B28: kg | C28: 8.52 | E28: =C28*D28 -> 0
A29: Pork strog | B29: kg | C29: 13.13
A30: Gammon B&R BPM | B30: KG | C30: 6.3 | E30: =C30*D30 -> 0
A31: diced | B31: kg | C31: 8.96 | E31: =C31*D31 -> 0
A32: Shoulder | B32: kg | C32: 5.32 | E32: =C32*D32 -> 0
A33: Frankfurets BPM | B33: kg | C33: 10.99 | E33: =C33*D33 -> 0
A34: Sausage 8's cmb | B34: PACK | C34: 7.15 | D34: 4 | E34: =C34*D34 -> 28.6
A35: BPM Cocktail 32's | B35: kg | C35: 7.27 | E35: =C35*D35 -> 0
A36: BPM chipolatas 16's | B36: kg | C36: 6.7 | E36: =C36*D36 -> 0
A37: Ham BPM | B37: kg | C37: 11.3 | E37: =C37*D37 -> 0
A38: Gluten free sausage BPM | B38: KG | C38: 22.08 | E38: =C38*D38 -> 0
A39: Sausage meat | B39: kg | C39: 3.84 | E39: =C39*D39 -> 0
A40: Turkey | E40: =C40*D40 -> 0
A41: TURKEY breast boneless BPM | B41: kg | C41: 7.41 | E41: =C41*D41 -> 0
A42: TURKEY JOINT | B42: 5.250kg | C42: 10 | E42: =C42*D42 -> 0
...

Sheet Frozen
A1: holroyd howe
A2: Frozen
A4: ITEM | B4: UNIT | C4: PRICE | D4: QUANTITY | E4: TOTAL
A5: Bread products
A6: Hot dog roll | B6: 1x48 | C6: 6.05 | D6: 0 | E6: =C6*D6 -> 0
A7: Gluten free pizza bases | B7: each | C7: 2.28 | D7: 0 | E7: =C7*D7 -> 0
A8: Naan Bread | B8: pck | C8: 1.34 | D8: 0 | E8: =C8*D8 -> 0
A9: NYBC plain bagel | B9: x 48 | C9: 18.07 | D9: 0 | E9: =C9*D9 -> 0
A10: Trad Crumpets | B10: x96 | C10: 22.94 | D10: 0 | E10: =C10*D10 -> 0
A11: Burger buns | B11: 1*48 | C11: 7.4 | D11: 0 | E11: =C11*D11 -> 0
A12: Danish pastries | E12: =C12*D12 -> 0
A13: Sultana scone | B13: 1x50 | C13: 11.76 | E13: =C13*D13 -> 0
A14: Mini danish Pastry selection | B14: Box | C14: 36.98 | D14: 1 | E14: =C14*D14 -> 36.98
A15: Oat & rasin cookie | B15: 1x90 | C15: 17.53 | D15: 0 | E15: =C15*D15 -> 0
A16: Bidfood Croissant pre pack | B16: 1x32 | C16: 19.03 | D16: 0.5 | E16: =C16*D16 -> 9.515
A17: Fruit | E17: =C17*D17 -> 0
A18: Blackberries | B18: 1kg | C18: 8.64 | D18: 2 | E18: =C18*D18 -> 17.28
A19: Blueberries | B19: 1kg | C19: 6.38 | D19: 0 | E19: =C19*D19 -> 0
A20: Raspberries | B20: 500 G | C20: 6.68 | D20: 0 | E20: =C20*D20 -> 0
A21: mango | B21: 1kg | D21: 0
A22: Strawberries | B22: 1kg | C22: 3.97 | D22: 0 | E22: =C22*D22 -> 0
A23: Fruit Of The Forest | B23: 1 KG | C23: 4.95 | D23: 5 | E23: =C23*D23 -> 24.75
A24: Vegetables & Potatoes | E24: =C24*D24 -> 0
A25: Sliced peppers | B25: 1kg | C25: 2.47
A26: Peas | B26: 2.5kg | C26: 3.31 | D26: 0 | E26: =C26*D26 -> 0
A27: Sweetcorn | B27: 2.5kg | C27: 4.98 | D27: 0 | E27: =C27*D27 -> 0
A28: fries | B28: box | C28: 39.94 | D28: 0 | E28: =C28*D28 -> 0
A29: potato waffles | B29: 2kg | C29: 7.08 | D29: 0 | E29: =C29*D29 -> 0
A30: Frozen onions | B30: 1kg | D30: 0
A31: Hash Browns | B31: 2.5kg | C31: 6.32 | D31: 6 | E31: =C31*D31 -> 37.92
A32: Snack items | E32: =C32*D32 -> 0
A33: Cheese & tom pizza slab Bidfood | B33: 4*box | C33: 17.33 | D33: 0 | E33: =C33*D33 -> 0
A34: Quorn vegan sausage | B34: 2-2.04kg | C34: 15.21 | D34: 0 | E34: =C34*D34 -> 0
A35: Onion Baji's | B35: box | C35: 12.55 | D35: 0 | E35: =C35*D35 -> 0
A36: GLUTEN FREE SAUSAGES | B36: pkt | C36: 12.75 | D36: 0.5 | E36: =C36*D36 -> 6.375
A37: Frozen Chicken Burgers | B37: box | C37: 29.21 | D37: 0 | E37: =C37*D37 -> 0
A38: Sausage Rolls | B38: Box | C38: 30.49 | D38: 4 | E38: =C38*D38 -> 121.96
A39: Vegetarian Items | E39: =C39*D39 -> 0
A40: Gnocci | B40: case | C40: 5.53 | D40: 0 | E40: =C40*D40 -> 0
A41: Fish pie mix | B41: 910kg bag | C41: 14.58 | D41: 0 | E41: =C41*D41 -> 0
...

Sheet Dairy
A1: holroyd howe
A2: Dairy
A4: ITEM | B4: UNIT | C4: PRICE | D4: QUANTITY | E4: TOTAL
A5: Butter & Marg
A6: Phase Block | B6: 250gm | C6: 0.48 | D6: 150 | E6: =C6*D6 -> 72
A7: Butter portions Bidfood | B7: 1 x 100 | C7: 5.98 | E7: =C7*D7 -> 0
A8: Butter rolls | B8: each | C8: 2.45
A9: Sunflower spread portions | B9: 1 x 100 | C9: 5.09 | D9: 13 | E9: =C9*D9 -> 66.17
A10: Cooking & Baking Phase Marg | B10: 250gm | C10: 0.35 | D10: 0 | E10: =C10*D10 -> 0
A11: Flora spread | B11: 2kg | C11: 5.62 | E11: =C11*D11 -> 0
A12: Bebo ptn | B12: 100 | C12: 5.32 | E12: =C12*D12 -> 0
A13: Margarine soft spread Bidfood | B13: 2kg | C13: 2.9 | E13: =C13*D13 -> 0
A14: Stork soft spread | B14: 2kg | C14: 6.01 | D14: 0 | E14: =C14*D14 -> 0
A15: Cheese | E15: =C15*D15 -> 0
A16: Brie (Cheese Cellar) | B16: 1.1kg | C16: 8.45 | D16: 0 | E16: =C16*D16 -> 0
A17: Cheddar mild grated (WHD) | B17: 2 kg | C17: 9.67 | D17: 3 | E17: =C17*D17 -> 29.01
A18: cheese portions x50 | B18: box | C18: 6.37 | D18: 0 | E18: =C18*D18 -> 0
A19: Cheddar block | B19: 5kg | C19: 27.65 | D19: 0 | E19: =C19*D19 -> 0
A20: Cheddar mild sliced (WHD) | B20: 1kg | C20: 6.15 | D20: 3 | E20: =C20*D20 -> 18.45
A21: Cream cheese - full fat ((WHD) | B21: 2kg | C21: 8.29 | D21: 0 | E21: =C21*D21 -> 0
A22: Goats log (WHD) | B22: 1kg | C22: 10 | D22: 0 | E22: =C22*D22 -> 0
A23: Feta Cheese WHD | B23: 900g | C23: 8.41 | D23: 1 | E23: =C23*D23 -> 8.41
A24: Parmesan Grated (WHD) | B24: kg | C24: 10.56 | D24: 0 | E24: =C24*D24 -> 0
A25: Cheese Haloumi | B25: 250g | C25: 2.85 | D25: 1 | E25: =C25*D25 -> 2.85
A26: Italian Style cheese grated (WHD) | B26: 1kg | C26: 10.56 | D26: 0 | E26: =C26*D26 -> 0
A27: boccocino balls | B27: 1kg | C27: 9.07 | D27: 1 | E27: =C27*D27 -> 9.07
A28: Mozzarella grated | B28: 2kg | C28: 13.05 | D28: 4 | E28: =C28*D28 -> 52.2
A29: Tofu - plain (Veg Exp) | B29: 3kg | C29: 20.11 | E29: =C29*D29 -> 0
A30: Violife vegan cheese | B30: 200g pk | C30: 2.07 | D30: 0 | E30: =C30*D30 -> 0
A31: Grano Padano | B31: 1kg | C31: 15.47 | D31: 0 | E31: =C31*D31 -> 0
A32: Milk & Cream | E32: =C32*D32 -> 0
A33: Whipping cream WHD UHT KERRYMAID | B33: 1ltr | C33: 3.73 | E33: =C33*D33 -> 0
A34: Soured cream | B34: 2kg | C34: 6.33 | D34: 0 | E34: =C34*D34 -> 0
A35: Eggs - medium free range Bidfood | B35: each | C35: 0.25 | D35: 150 | E35: =C35*D35 -> 37.5
A36: Eggs - Whole Egg Liquid Bidfood | B36: 1ltr | C36: 3.6 | D36: 9 | E36: =C36*D36 -> 32.4
A37: milk coconut | B37: 1ltr | D37: 1
A38: oat milk | B38: 1ltr | D38: 4
A39: Milk - alpro soya (WHD) | B39: 1 Litre | C39: 1.45 | D39: 2 | E39: =C39*D39 -> 2.9
A40: Milk - pergal | B40: Each | C40: 9.04 | D40: 0 | E40: =C40*D40 -> 0
A41: Milk skimmed | B41: 1 ltr | C41: 0.76 | E41: =C41*D41 -> 0
...

Sheet Fruit_&_Veg
A1: holroyd howe
A2: Fruit & Veg
A4: ITEM | C4: UNIT | D4: PRICE | E4: QUANTITY | F4: TOTAL
A5: misc fruit &veg left | F5: =D5*E5 -> 0
A6: Apple sGranny Smith CSL | C6: 18kg | D6: 33.84 | E6: 0 | F6: =D6*E6 -> 0
A7: Apples Braeburn CSL | B7: each | C7: 12kg | D7: 28.24 | E7: 0 | F7: =D7*E7 -> 0
A8: Avocado | C8: each | D8: 1.5 | E8: 0 | F8: =D8*E8 -> 0
A9: pineapple CSL | C9: each | D9: 2.04 | E9: 0 | F9: =D9*E9 -> 0
A10: Bananas CSL | C10: 1kg | D10: 1.78 | F10: =D10*E10 -> 0
A11: Blueberries | C11: punnet | D11: 2.86 | E11: 0 | F11: =D11*E11 -> 0
A12: Clementines | C12: 10kg | D12: 16.38 | E12: 0 | F12: =D12*E12 -> 0
A13: Grapes green | B13: 1X1KG | C13: 5kg | D13: 26.32 | E13: 0 | F13: =D13*E13 -> 0
A14: Grapes red | C14: kg | D14: 5.32 | E14: 0 | F14: =D14*E14 -> 0
A15: Lemons | B15: EACH | C15: each | D15: 0.28 | E15: 3 | F15: =D15*E15 -> 0.84
A16: Limes | C16: Each | D16: 0.28 | F16: =D16*E16 -> 0
A17: Melon cantaloupe | B17: EACH | C17: each | D17: 3.87 | E17: 0 | F17: =D17*E17 -> 0
A18: Melon galia | B18: EACH | C18: each | D18: 2 | E18: 0 | F18: =D18*E18 -> 0
A19: Melon honeydew CSL | B19: EACH | C19: each | D19: 2.55 | E19: 2 | F19: =D19*E19 -> 5.1
A20: Melon water CSL | B20: EACH | C20: Each | D20: 5.07 | E20: 3 | F20: =D20*E20 -> 15.21
A21: Oranges medium | B21: 1X1KG | C21: each | D21: 0.18 | E21: 5 | F21: =D21*E21 -> 0.9
A22: Pears conference CSL | C22: 1kg | D22: 2.41 | E22: 10 | F22: =D22*E22 -> 24.1
A23: Plums CSL | B23: EACH | C23: 5KG | D23: 18.06 | E23: 0 | F23: =D23*E23 -> 0
A24: Satsumas CSL | C24: 10kg | D24: 32.4 | E24: 0 | F24: =D24*E24 -> 0
A25: Strawberries | B25: 1X360 | C25: 250g | D25: 2.66 | E25: 0 | F25: =D25*E25 -> 0
A26: Basil CSL | B26: 1 BANG | C26: bunch | D26: 1.76 | E26: 2 | F26: =D26*E26 -> 3.52
A27: Chives | B27: 1 BANG | C27: bunch | D27: 1.69 | E27: 0 | F27: =D27*E27 -> 0
A28: Coriander CSL | B28: 1 BANG | C28: bunch | D28: 1.55 | E28: 1 | F28: =D28*E28 -> 1.55
A29: Dill CSL | B29: 1 BANG | C29: bunch | D29: 1.34 | E29: 0 | F29: =D29*E29 -> 0
A30: Mango | C30: each | D30: 1.5 | E30: 0 | F30: =D30*E30 -> 0
A31: oregano CSL | C31: bunch | D31: 2.23 | E31: 0 | F31: =D31*E31 -> 0
A32: Mint CSL | B32: 1 BANG | C32: bunch | D32: 1.43 | E32: 0 | F32: =D32*E32 -> 0
A33: Parsley | B33: 1 BANG | C33: bunch | D33: 1.69 | E33: 0 | F33: =D33*E33 -> 0
A34: Parsley flat CSL | C34: bunch | D34: 1.73 | E34: 0 | F34: =D34*E34 -> 0
A35: Rosemary CSL | B35: 1 BANG | C35: bunch | D35: 1.63 | E35: 1 | F35: =D35*E35 -> 1.63
A36: Sage | B36: 1 BANG | C36: bunch | D36: 1.43 | E36: 0 | F36: =D36*E36 -> 0
A37: Tarragon CSL | B37: 1 BANG | C37: bunch | D37: 2.12 | E37: 0 | F37: =D37*E37 -> 0
A38: Thyme CSL | B38: 1 BANG | C38: bunch | D38: 1.7 | E38: 1 | F38: =D38*E38 -> 1.7
A39: Asparagus x large CSL | C39: bunch | D39: 5.67 | E39: 0 | F39: =D39*E39 -> 0
A40: Aubergines | C40: 5kg | D40: 14.51 | E40: 0 | F40: =D40*E40 -> 0
A41: mixed chillies | C41: 1kg | D41: 8.43 | E41: 0 | F41: =D41*E41 -> 0
...

Sheet Retail
A1: holroyd howe
A2: Confectionery/retail
A4: ITEM | B4: UNIT | C4: PRICE | D4: QUANTITY | E4: TOTAL
A5: kp crisps | B5: 1x48 | C5: 19.13 | D5: 6 | E5: =C5*D5 -> 114.78
A6: Walkers crisps | B6: 1x48 | C6: 16.19 | D6: 0 | E6: =C6*D6 -> 0
A7: Mini Cheddars | B7: 30g bag | C7: 0 | D7: 0 | E7: =C7*D7 -> 0
A8: Kit kat 2 finger (1x48) | B8: 1 x 72 | C8: 20.95 | D8: 0 | E8: =C8*D8 -> 0
A9: boka bars | B9: 1x24 | D9: 6 | E9: =C9*D9 -> 0
A10: Milk powder | B10: 500g | C10: 4.79 | D10: 0 | E10: =C10*D10 -> 0
A11: Galaxy chocolate | B11: 750g | C11: 4.79 | D11: 0 | E11: =C11*D11 -> 0
A12: Kenco vending | B12: 300g | C12: 9.36 | D12: 0 | E12: =C12*D12 -> 0
A13: Kenco decaff vending | B13: 300g | C13: 9.36 | D13: 0 | E13: =C13*D13 -> 0
A14: Total | E14: =SUM(E5:E13) -> 114.78

Sheet Cleaning
A1: holroyd howe
A2: CLEANING STOCK
A4: ITEM | B4: ITEM CODE | C4: PACK SIZE | D4: PRICE | E4: QUANTITY | F4: STOCK VALUE
A5: Aprons disposable | C5: 1X100 | D5: 5 | E5: 1.5 | F5: =D5*E5 -> 7.5
A6: Black Bags sacks GW5010B | C6: 1x200 | D6: 17.04 | E6: 2.4 | F6: =D6*E6 -> 40.896
A7: Blue vinyl gloves washup | B7: PO8262 | C7: per pair | D7: 0.65 | E7: 4 | F7: =D7*E7 -> 2.6
A8: Blue nitrile gloves med | B8: P09971 | C8: BOX | D8: 7.64 | E8: 3 | F8: =D8*E8 -> 22.92
A9: Blue nitrile gloves xl | B9: P09976 | C9: box | D9: 8.49 | E9: 6 | F9: =D9*E9 -> 50.94
A10: blue nitrle gloves large | B10: p10992 | C10: box | D10: 7.25
A11: Blue centrefeedroll 2ply | B11: M00864 | C11: each | D11: 2.32 | E11: 20 | F11: =D11*E11 -> 46.4
A12: Bactericidal handsoap | B12: 60000 | C12: 5 lt | D12: 12.62 | E12: 5 | F12: =D12*E12 -> 63.1
A13: Red Disposable Aprons | B13: PO9515 | C13: 1x100 | D13: 14.7 | E13: 0 | F13: =D13*E13 -> 0
A14: Degreaser concerntrated | B14: 098200 | C14: 2litre | D14: 25.94 | F14: =D14*E14 -> 0
A15: Ultra floor cleaner | B15: 41000 | C15: 5ltr | D15: 11.37 | E15: 0 | F15: =D15*E15 -> 0
A16: pro supplies floor cleaner | B16: 35881 | C16: 2 x 5litre | D16: 29.91 | E16: 2.5 | F16: =D16*E16 -> 74.775
A17: Glass & stainless steel cleaner | B17: 70200 | C17: 750ML | D17: 1.99 | E17: 0 | F17: =D17*E17 -> 0
A18: Limescale Remover | B18: 50600 | C18: 5 ltr | D18: 8.42 | E18: 0.5 | F18: =D18*E18 -> 4.21
A19: Tannin remover | C19: 10kg | D19: 31.25 | E19: 0 | F19: =D19*E19 -> 0
A20: Machine detergent | C20: 20litre | D20: 36.86 | E20: 5.5 | F20: =D20*E20 -> 202.73
A21: Machine rinse aid | C21: 20litre | D21: 43.16 | E21: 3 | F21: =D21*E21 -> 129.48
A22: pro supplies washing liquid | B22: 14381 | C22: 2x5lirtre | D22: 19.96 | E22: 6.5 | F22: =D22*E22 -> 129.74
A23: Bacti sinkwash | B23: 30000 | C23: 5lt | D23: 11.21 | E23: 0 | F23: =D23*E23 -> 0
A24: Oven cleaner Rational care | C24: 1x150 | D24: 73 | E24: 1 | F24: =D24*E24 -> 73
A25: Oven cleaner Rational detergent | C25: 1x100 | D25: 51.52 | E25: 1 | F25: =D25*E25 -> 51.52
A26: Oven cleaner Rational rinse | C26: 1x50 | D26: 58.47 | E26: 1.1 | F26: =D26*E26 -> 64.317
A27: Oven cleaner spray - foaming | C27: 750ml | D27: 2.5 | E27: 0 | F27: =D27*E27 -> 0
A28: Probe wipes | B28: PO6657 | C28: 1 x200 | D28: 4.99 | E28: 6.5 | F28: =D28*E28 -> 32.435
A29: Salad wash | B29: 95500 | C29: 5ltr | D29: 36.25 | E29: 2.5 | F29: =D29*E29 -> 90.625
A30: Salt - granular | B30: N00999 | C30: 25kg | D30: 11.17 | E30: 1.4 | F30: =D30*E30 -> 15.638
A31: Sanitiser L/Conc | B31: 95800 | C31: 2 lt | D31: =48.06/2 -> 24.03 | E31: 0 | F31: =D31*E31 -> 0
A32: Sanitiser powder | C32: 10kg | D32: 32.61 | E32: 0.5 | F32: =D32*E32 -> 16.305
A33: Sanitiser spray | B33: 14317 | C33: 6x750ml | D33: 3.65 | E33: 9 | F33: =D33*E33 -> 32.85
A34: light weight cloth blue | B34: PO7746 | C34: 1x100 | D34: 8.79 | E34: 6 | F34: =D34*E34 -> 52.74
A35: Heavy weight cloth blue | B35: PO7754 | C35: 1 x 25 | D35: 6.71 | E35: 0 | F35: =D35*E35 -> 0
A36: Scourers - green | B36: po3243 | C36: 1X10 | D36: 2.22 | E36: 5 | F36: =D36*E36 -> 11.1
A37: heavy duty scourer | B37: PO9377 | C37: 1x10 | D37: 9.43 | E37: 0 | F37: =D37*E37 -> 0
A38: Griddle Pads | B38: PO5339 | C38: 1x pk | D38: 3.8 | E38: 1.5 | F38: =D38*E38 -> 5.7
A39: PPE
A40: Respirator | B40: 100700 | C40: each | D40: 0.93 | E40: 12 | F40: =D40*E40 -> 11.16
A41: Safety goggles | B41: 100600 | C41: each | D41: 3.49 | E41: 12 | F41: =D41*E41 -> 41.88
...

Sheet Disposables
A1: Holroyd Howe
A2: Disposables
A4: ITEM | B4: SIZE | C4: PRICE | D4: QUANTITY | E4: TOTAL
A5: HH logo paper | B5: 1x1000 | C5: 57.62 | D5: 0.4 | E5: =C5*D5 -> 23.048
A7: Daily catch paper | B7: GO6582 | C7: 38.22 | D7: 0.5 | E7: =C7*D7 -> 19.11
A8: White Paper lunch bags | B8: 1x250 | C8: 25 | E8: =C8*D8 -> 0
A9: brown wax paper | B9: 460x710 | C9: 78.95 | D9: 1 | E9: =C9*D9 -> 78.95
A10: Brown sos paper bag GO1203 | B10: 1x250 | C10: 13.02 | D10: 1 | E10: =C10*D10 -> 13.02
A11: Muffin cases tulip (Café C) | B11: 1x1000 | C11: 20.36 | D11: 0.3 | E11: =C11*D11 -> 6.108
A12: Napkins white cocktail | B12: 8139 | C12: 34.09 | D12: 0.6 | E12: =C12*D12 -> 20.454
A13: D04410 Blue napkins | B13: 2000 | C13: 60.08 | D13: 0 | E13: =C13*D13 -> 0
A14: recycle napkins D08240 | B14: x3000 | C14: 39.12 | D14: 0 | E14: =C14*D14 -> 0
A15: 4oz paper cup Nisbetts | B15: X1000 | C15: 34.99 | D15: 1.6 | E15: =C15*D15 -> 55.984
A16: 8oz paper cups BO5061 | B16: x500 | C16: 35.32 | D16: 0.3 | E16: =C16*D16 -> 10.596
A17: White paper cups 4oz B01502 | B17: 1x1000 | C17: 35.72 | D17: 1 | E17: =C17*D17 -> 35.72
A18: Cups - Brown B05209 | B18: 1x500 | C18: 88.4 | D18: 0 | E18: =C18*D18 -> 0
A19: brown soup pots | C19: 50.11 | D19: 0.8 | E19: =C19*D19 -> 40.088
A20: brown soup lids | B20: 1x500 | C20: 54.84 | D20: 0.8 | E20: =C20*D20 -> 43.872
A21: 8 0z cup lids | B21: 1000 | C21: 42.06 | D21: 2.5 | E21: =C21*D21 -> 105.15
A22: Kraft standard s/w wedge G07425 | B22: x500 | C22: 52.36 | D22: 0 | E22: =C22*D22 -> 0
A23: 4oz portion pot H07091 plastic | B23: 1x2000 | C23: 85.38 | D23: 0.7 | E23: =C23*D23 -> 59.766
A24: 12oz lid | B24: x1000 | C24: 130.61 | D24: 1 | E24: =C24*D24 -> 130.61
A25: 8.6 wooden skewer Bunzl E00543 | B25: 200 | C25: 2.7 | D25: 1.5 | E25: =C25*D25 -> 4.05
A26: Teppo gushi (gun shaped | B26: Pack | C26: 5.4 | D26: 0 | E26: =C26*D26 -> 0
A27: Wooden spoons | B27: pck 1000 | C27: 20.78 | D27: 0.3 | E27: =C27*D27 -> 6.234
A28: sustain wooden knife | B28: pck 1000 | C28: 20.78 | D28: 0.5 | E28: =C28*D28 -> 10.39
A29: sustain wooden fork | B29: Pack 1000 | C29: 20.78 | D29: 0.5 | E29: =C29*D29 -> 10.39
A30: Cling Film - wrapmaster 45cm HO1755 | B30: x3 | C30: 30.98 | D30: 2 | E30: =C30*D30 -> 61.96
A31: Good to go parchment 45cm GO6939 | B31: roll | C31: 9.46 | D31: 6 | E31: =C31*D31 -> 56.76
A32: Foil good to go | B32: roll | C32: 8.87 | D32: 1.4 | E32: =C32*D32 -> 12.418
A33: Piping bags | B33: roll | C33: 12.02 | D33: 1 | E33: =C33*D33 -> 12.02
A34: Remmerco pud pots | B34: 1x100 | C34: 129.5 | D34: 0.8 | E34: =C34*D34 -> 103.6
A35: Diposable face mask | B35: x50 | C35: 22 | D35: 0 | E35: =C35*D35 -> 0
A36: Fresco salad bowls | B36: box | C36: 61.78 | D36: 0.5 | E36: =C36*D36 -> 30.89
A37: Wrapmaster small dispenser | B37: each | C37: 37.61 | D37: 0 | E37: =C37*D37 -> 0
... A39: Wrapmaster dispenser | B39: each | C39: 46.7 | D39: 7 | E39: =C39*D39 -> 326.9
A40: Xmas slip covers | B40: DO8065 | C40: 83.93 | D40: 0
A41: Xmas napkins | B41: box | C41: 85.35 | D41: 0.8 | E41: =C41*D41 -> 68.28
A42: Blue plasters assorted | B42: 1x150 | C42: 9.7 | D42: 0.5 | E42: =C42*D42 -> 4.85
A43: Lables | E43: =C43*D43 -> 0
...
